Workbook

Sheet SSP assumptions
B1: 2000-2020 calibration | C1: 2020-2050 extrapolation
A2: Indicator | B2: standard scenario | C2: SSP1 | D2: SSP2 | E2: SSP3 | F2: ref
A3: Population growth
A4: Narrative | B4: - Decreasing growth rates since 1990s | C4: - Increase on the long run | D4: - Population maintains current growth pattern | E4: - Population growth decreases, with potential sharp decrease on the long run | F4: - SSP Narratives - Analysis of population distribution 1980-2020
A5: Quantification - max | B5: 0.0329 | C5: 0.0227 | D5: 0.0157 | E5: 0.0107
A6: Quantification - min | B6: 0.0107
A7: Quantification total HH | B7: 180405 | C7: =C8/(3.8*50) -> 217503.28 | D7: =D8/(3.8*50) -> 208533.99 | E7: =E8/(3.8*50) -> 200640.72
A8: mi people | B8: =39.6214587249692*1000000 -> 39621459 | C8: =41.3256230967465*1000000 -> 41325623 | D8: =39.6214587249692*1000000 -> 39621459 | E8: =38.1217364291978*1000000 -> 38121736 | F8: - Populations projections for Indonesia in the IIASA SSP Database, inverted (SSP1=SSP3)
A9: Number of deprived HH
A10: Narrative | B10: - Located in the outskirts - Depend on motorbikes or public transportation - Differences to LI? | C10: - Small reduction | D10: - Slight increase (25%) | E10: - Growth much above the mean | F10: - SSP Narratives - GDP distribution raster in Kummu et al.2025 - Analysis in Janssen & Molder 2022
A11: Quantification - 2000
A12: Quantification - 2020 | B12: 0.1 | C12: 7 | D12: 13 | E12: 25
A13: Number of low income HH
A14: Narrative | B14: - Located in the outskirts - Depend on motorbikes or public transportation - Differences to DP? | C14: - Strong reduction | D14: - Slight increase (25%) | E14: - Growth much above the mean | F14: - SSP Narratives - GDP distribution raster in Kummu et al.2025 - Analysis in Janssen & Molder 2022
A15: Quantification - 2000
A16: Quantification - 2020 | B16: 0.43 | C16: 23 | D16: 48 | E16: 50
A17: Number of middle income HH
A18: Narrative | B18: - | C18: - Strong increase | D18: - Stable | E18: - Strong decrease
A19: Quantification - 2000
A20: Quantification - 2020 | B20: 0.2 | C20: 33 | D20: 20 | E20: 15
A21: Number of high income HH
A22: Narrative | B22: - Cluster around the CBD - Favour location of large houses | C22: - Growth above the mean | D22: - Small decrease | E22: - Strong decrease | F22: - SSP Narratives - GDP distribution raster in Kummu et al.2025 - Analysis in Janssen & Molder 2022
A23: Quantification - 2000
A24: Quantification - 2020 | B24: 0.27 | C24: 37 | D24: 19 | E24: 10
A25: Consistency check | B25: =SUM(B24,B20,B16,B12) -> 1 | C25: =SUM(C24,C20,C16,C12) -> 100 | D25: =SUM(D24,D20,D16,D12) -> 100 | E25: =SUM(E24,E20,E16,E12) -> 100
A26: Suburban centres Utility
A27: Narrative | B27: - Strong suburban development - Suburban centers have little influence (mostly roads) | D27: - Small decrease | E27: - Strong decrease
A28: Quantification - max
A29: Quantification - min
A30: Neighbour
A31: Narrative | B31: ?
A32: Quantification - max
A33: Quantification - min
A34: Built up utility
A35: Narrative | B35: - Edge expansion growth seems to dominate new cells over most periods
A36: Quantification - max
A37: Quantification - min
A38: CBD utility
A39: Narrative | B39: - No expression in expansion - Income levels concentric around these features - High income clusters around these features | F39: - Analysis in Janssen & Molder 2022
A40: Quantification - max
...

Sheet SSP paper
D1: Urbanisation | F1: Population | H1: Urbanisation change rate | K1: Population changec rate
C2: Total area (km²) | D2: Total area 2025 (km²) | E2: Urbanisation Rate | F2: Total (mi) | G2: Mean density 2025 (pop/km²) | H2: 1980-1990 | I2: 2015-2025 | J2: 1980-2025 | K2: 1980-1990 | L2: 1990-2015 | M2: 2015-2025 | N2: 1980-2025 | T2: Urban area 1975 | U2: Urban area 1990
A3: Jabodetabek region | C3: =SUM(C5:C19) -> 5748.554 | D3: =SUM(D5:D19) -> 927.0548 | E3: =AVERAGE(E5:E19) -> 0.31854665 | F3: =SUM(F5:F19) -> 39.172824 | G3: =AVERAGE(G5:G19) -> 14689.289 | H3: =AVERAGE(H5:H19) -> 1.6473333 | I3: =AVERAGE(I5:I19) -> 0.438 | J3: =AVERAGE(J5:J19) -> 1.2326667 | K3: =AVERAGE(K5:K19) -> 3.7306667 | L3: =AVERAGE(L5:L19) -> 2.51 | M3: =AVERAGE(M5:M19) -> 1.5706667 | N3: =AVERAGE(N5:N19) -> 2.596 | T3: 525.22114 | U3: 643.28309 | V3: row_refs
A4: Core | G4: =AVERAGE(G5:G9) -> 19130.132
B5: South Jakarta City | C5: =GHSL!C2 -> 144.813 | D5: =GHSL!$X2/1000000 -> 56.194907 | E5: =D5/C5 -> 0.38805154 | F5: =GHSL!$N2/1000000 -> 2.541613 | G5: =GHSL!$N2/C5 -> 17551 | H5: =ROUND(AVERAGE(INDIRECT(_xlfn.CONCAT($B$20,"!",LEFT(H$20,2),$V5,RIGHT(H$20,3),$V5),TRUE)),2) -> 0.9 | I5: =ROUND(AVERAGE(INDIRECT(_xlfn.CONCAT($B$20,"!",LEFT(I$20,2),$V5,RIGHT(I$20,3),$V5),TRUE)),2) -> 0.04 | J5: =ROUND(AVERAGE(INDIRECT(_xlfn.CONCAT($B$20,"!",LEFT(J$20,2),$V5,RIGHT(J$20,3),$V5),TRUE)),2) -> 0.32 | K5: =ROUND(AVERAGE(INDIRECT(_xlfn.CONCAT($B$20,"!",LEFT(K$20,2),$V5,RIGHT(K$20,3),$V5),TRUE)),2) -> 3.13 | L5: =ROUND(AVERAGE(INDIRECT(_xlfn.CONCAT($B$20,"!",LEFT(L$20,2),$V5,RIGHT(L$20,3),$V5),TRUE)),2) -> 0.85 | M5: =ROUND(AVERAGE(INDIRECT(_xlfn.CONCAT($B$20,"!",LEFT(M$20,2),$V5,RIGHT(M$20,3),$V5),TRUE)),2) -> 1.07 | N5: =ROUND(AVERAGE(INDIRECT(_xlfn.CONCAT($B$20,"!",LEFT(N$20,2),$V5,RIGHT(N$20,3),$V5),TRUE)),2) -> 1.33 | V5: 2 | X5: =_xlfn.CONCAT("raw!BC",V5,":BD",V5) -> raw!BC2:BD2 | Z5: =_xlfn.CONCAT("raw!AV",$V5,":BD",$V5) -> raw!AV2:BD2
B6: East Jakarta City | C6: =GHSL!C3 -> 184.658 | D6: =GHSL!$X3/1000000 -> 66.253606 | E6: =D6/C6 -> 0.35879088 | F6: =GHSL!$N3/1000000 -> 3.3431318 | G6: =GHSL!$N3/C6 -> 18104.451 | H6: =ROUND(AVERAGE(INDIRECT(_xlfn.CONCAT($B$20,"!",LEFT(H$20,2),$V6,RIGHT(H$20,3),$V6),TRUE)),2) -> 0.96 | I6: =ROUND(AVERAGE(INDIRECT(_xlfn.CONCAT($B$20,"!",LEFT(I$20,2),$V6,RIGHT(I$20,3),$V6),TRUE)),2) -> 0.12 | J6: =ROUND(AVERAGE(INDIRECT(_xlfn.CONCAT($B$20,"!",LEFT(J$20,2),$V6,RIGHT(J$20,3),$V6),TRUE)),2) -> 0.43 | K6: =ROUND(AVERAGE(INDIRECT(_xlfn.CONCAT($B$20,"!",LEFT(K$20,2),$V6,RIGHT(K$20,3),$V6),TRUE)),2) -> 3.13 | L6: =ROUND(AVERAGE(INDIRECT(_xlfn.CONCAT($B$20,"!",LEFT(L$20,2),$V6,RIGHT(L$20,3),$V6),TRUE)),2) -> 0.8 | M6: =ROUND(AVERAGE(INDIRECT(_xlfn.CONCAT($B$20,"!",LEFT(M$20,2),$V6,RIGHT(M$20,3),$V6),TRUE)),2) -> 1.07 | N6: =ROUND(AVERAGE(INDIRECT(_xlfn.CONCAT($B$20,"!",LEFT(N$20,2),$V6,RIGHT(N$20,3),$V6),TRUE)),2) -> 1.3 | V6: 3 | X6: =_xlfn.CONCAT("raw!BC",V6,":BD",V6) -> raw!BC3:BD3 | Z6: =_xlfn.CONCAT("raw!AV",$V6,":BD",$V6) -> raw!AV3:BD3
B7: Central Jakarta City | C7: =GHSL!C4 -> 47.887 | D7: =GHSL!$X4/1000000 -> 18.722782 | E7: =D7/C7 -> 0.39097839 | F7: =GHSL!$N4/1000000 -> 1.0305016 | G7: =GHSL!$N4/C7 -> 21519.444 | H7: =ROUND(AVERAGE(INDIRECT(_xlfn.CONCAT($B$20,"!",LEFT(H$20,2),$V7,RIGHT(H$20,3),$V7),TRUE)),2) -> 0.77 | I7: =ROUND(AVERAGE(INDIRECT(_xlfn.CONCAT($B$20,"!",LEFT(I$20,2),$V7,RIGHT(I$20,3),$V7),TRUE)),2) -> 0.03 | J7: =ROUND(AVERAGE(INDIRECT(_xlfn.CONCAT($B$20,"!",LEFT(J$20,2),$V7,RIGHT(J$20,3),$V7),TRUE)),2) -> 0.19 | K7: =ROUND(AVERAGE(INDIRECT(_xlfn.CONCAT($B$20,"!",LEFT(K$20,2),$V7,RIGHT(K$20,3),$V7),TRUE)),2) -> 2.99 | L7: =ROUND(AVERAGE(INDIRECT(_xlfn.CONCAT($B$20,"!",LEFT(L$20,2),$V7,RIGHT(L$20,3),$V7),TRUE)),2) -> -0.06 | M7: =ROUND(AVERAGE(INDIRECT(_xlfn.CONCAT($B$20,"!",LEFT(M$20,2),$V7,RIGHT(M$20,3),$V7),TRUE)),2) -> 0.99 | N7: =ROUND(AVERAGE(INDIRECT(_xlfn.CONCAT($B$20,"!",LEFT(N$20,2),$V7,RIGHT(N$20,3),$V7),TRUE)),2) -> 0.84 | V7: 4 | X7: =_xlfn.CONCAT("raw!BC",V7,":BD",V7) -> raw!BC4:BD4 | Z7: =_xlfn.CONCAT("raw!AV",$V7,":BD",$V7) -> raw!AV4:BD4
B8: West Jakarta City | C8: =GHSL!C5 -> 125.47 | D8: =GHSL!$X5/1000000 -> 48.004584 | E8: =D8/C8 -> 0.3825981 | F8: 3.0028169 | G8: =GHSL!$N5/C8 -> 23932.549 | H8: =ROUND(AVERAGE(INDIRECT(_xlfn.CONCAT($B$20,"!",LEFT(H$20,2),$V8,RIGHT(H$20,3),$V8),TRUE)),2) -> 0.93 | I8: =ROUND(AVERAGE(INDIRECT(_xlfn.CONCAT($B$20,"!",LEFT(I$20,2),$V8,RIGHT(I$20,3),$V8),TRUE)),2) -> 0.08 | J8: =ROUND(AVERAGE(INDIRECT(_xlfn.CONCAT($B$20,"!",LEFT(J$20,2),$V8,RIGHT(J$20,3),$V8),TRUE)),2) -> 0.4 | K8: =ROUND(AVERAGE(INDIRECT(_xlfn.CONCAT($B$20,"!",LEFT(K$20,2),$V8,RIGHT(K$20,3),$V8),TRUE)),2) -> 3.15 | L8: =ROUND(AVERAGE(INDIRECT(_xlfn.CONCAT($B$20,"!",LEFT(L$20,2),$V8,RIGHT(L$20,3),$V8),TRUE)),2) -> 1.13 | M8: =ROUND(AVERAGE(INDIRECT(_xlfn.CONCAT($B$20,"!",LEFT(M$20,2),$V8,RIGHT(M$20,3),$V8),TRUE)),2) -> 1.08 | N8: =ROUND(AVERAGE(INDIRECT(_xlfn.CONCAT($B$20,"!",LEFT(N$20,2),$V8,RIGHT(N$20,3),$V8),TRUE)),2) -> 1.47 | V8: 5 | X8: =_xlfn.CONCAT("raw!BC",V8,":BD",V8) -> raw!BC5:BD5 | Z8: =_xlfn.CONCAT("raw!AV",$V8,":BD",$V8) -> raw!AV5:BD5
B9: North Jakarta City | C9: =GHSL!C6 -> 140.264 | D9: =GHSL!$X6/1000000 -> 45.598996 | E9: =D9/C9 -> 0.32509408 | F9: 2.0398893 | G9: =GHSL!$N6/C9 -> 14543.214 | H9: =ROUND(AVERAGE(INDIRECT(_xlfn.CONCAT($B$20,"!",LEFT(H$20,2),$V9,RIGHT(H$20,3),$V9),TRUE)),2) -> 1.1 | I9: =ROUND(AVERAGE(INDIRECT(_xlfn.CONCAT($B$20,"!",LEFT(I$20,2),$V9,RIGHT(I$20,3),$V9),TRUE)),2) -> 0.27 | J9: =ROUND(AVERAGE(INDIRECT(_xlfn.CONCAT($B$20,"!",LEFT(J$20,2),$V9,RIGHT(J$20,3),$V9),TRUE)),2) -> 0.73 | K9: =ROUND(AVERAGE(INDIRECT(_xlfn.CONCAT($B$20,"!",LEFT(K$20,2),$V9,RIGHT(K$20,3),$V9),TRUE)),2) -> 3.12 | L9: =ROUND(AVERAGE(INDIRECT(_xlfn.CONCAT($B$20,"!",LEFT(L$20,2),$V9,RIGHT(L$20,3),$V9),TRUE)),2) -> 0.79 | M9: =ROUND(AVERAGE(INDIRECT(_xlfn.CONCAT($B$20,"!",LEFT(M$20,2),$V9,RIGHT(M$20,3),$V9),TRUE)),2) -> 1.05 | N9: =ROUND(AVERAGE(INDIRECT(_xlfn.CONCAT($B$20,"!",LEFT(N$20,2),$V9,RIGHT(N$20,3),$V9),TRUE)),2) -> 1.3 | V9: 6 | X9: =_xlfn.CONCAT("raw!BC",V9,":BD",V9) -> raw!BC6:BD6 | Z9: =_xlfn.CONCAT("raw!AV",$V9,":BD",$V9) -> raw!AV6:BD6
A10: Inner suburbs | H10: =ROUND(AVERAGE(INDIRECT(_xlfn.CONCAT($B$20,"!",LEFT(H$20,2),$V10,RIGHT(H$20,3),$V10),TRUE)),2) -> 1.65 | I10: =ROUND(AVERAGE(INDIRECT(_xlfn.CONCAT($B$20,"!",LEFT(I$20,2),$V10,RIGHT(I$20,3),$V10),TRUE)),2) -> 0.44 | J10: =ROUND(AVERAGE(INDIRECT(_xlfn.CONCAT($B$20,"!",LEFT(J$20,2),$V10,RIGHT(J$20,3),$V10),TRUE)),2) -> 1.23 | K10: =ROUND(AVERAGE(INDIRECT(_xlfn.CONCAT($B$20,"!",LEFT(K$20,2),$V10,RIGHT(K$20,3),$V10),TRUE)),2) -> 3.73 | L10: =ROUND(AVERAGE(INDIRECT(_xlfn.CONCAT($B$20,"!",LEFT(L$20,2),$V10,RIGHT(L$20,3),$V10),TRUE)),2) -> 2.51 | M10: =ROUND(AVERAGE(INDIRECT(_xlfn.CONCAT($B$20,"!",LEFT(M$20,2),$V10,RIGHT(M$20,3),$V10),TRUE)),2) -> 1.57 | N10: =ROUND(AVERAGE(INDIRECT(_xlfn.CONCAT($B$20,"!",LEFT(N$20,2),$V10,RIGHT(N$20,3),$V10),TRUE)),2) -> 2.6
B11: Bogor City | C11: =GHSL!C9 -> 111.74 | D11: =GHSL!$X9/1000000 -> 28.748272 | E11: =D11/C11 -> 0.25727825 | F11: =GHSL!$N9/1000000 -> 1.3592905 | G11: =GHSL!$N9/C11 -> 12164.762 | H11: =ROUND(AVERAGE(INDIRECT(_xlfn.CONCAT($B$20,"!",LEFT(H$20,2),$V11,RIGHT(H$20,3),$V11),TRUE)),2) -> 1.84 | I11: =ROUND(AVERAGE(INDIRECT(_xlfn.CONCAT($B$20,"!",LEFT(I$20,2),$V11,RIGHT(I$20,3),$V11),TRUE)),2) -> 0.41 | J11: =ROUND(AVERAGE(INDIRECT(_xlfn.CONCAT($B$20,"!",LEFT(J$20,2),$V11,RIGHT(J$20,3),$V11),TRUE)),2) -> 1.7 | K11: =ROUND(AVERAGE(INDIRECT(_xlfn.CONCAT($B$20,"!",LEFT(K$20,2),$V11,RIGHT(K$20,3),$V11),TRUE)),2) -> 0.94 | L11: =ROUND(AVERAGE(INDIRECT(_xlfn.CONCAT($B$20,"!",LEFT(L$20,2),$V11,RIGHT(L$20,3),$V11),TRUE)),2) -> 2.15 | M11: =ROUND(AVERAGE(INDIRECT(_xlfn.CONCAT($B$20,"!",LEFT(M$20,2),$V11,RIGHT(M$20,3),$V11),TRUE)),2) -> 1.56 | N11: =ROUND(AVERAGE(INDIRECT(_xlfn.CONCAT($B$20,"!",LEFT(N$20,2),$V11,RIGHT(N$20,3),$V11),TRUE)),2) -> 1.76 | V11: 9 | X11: =_xlfn.CONCAT("raw!BC",V11,":BD",V11) -> raw!BC9:BD9 | Z11: =_xlfn.CONCAT("raw!AV",$V11,":BD",$V11) -> raw!AV9:BD9
B12: Bekasi City | C12: =GHSL!C10 -> 214.092 | D12: =GHSL!$X10/1000000 -> 73.476896 | E12: =D12/C12 -> 0.34320244 | F12: =GHSL!$N10/1000000 -> 3.693744 | G12: =GHSL!$N10/C12 -> 17253.069 | H12: =ROUND(AVERAGE(INDIRECT(_xlfn.CONCAT($B$20,"!",LEFT(H$20,2),$V12,RIGHT(H$20,3),$V12),TRUE)),2) -> 1.54 | I12: =ROUND(AVERAGE(INDIRECT(_xlfn.CONCAT($B$20,"!",LEFT(I$20,2),$V12,RIGHT(I$20,3),$V12),TRUE)),2) -> 0.3 | J12: =ROUND(AVERAGE(INDIRECT(_xlfn.CONCAT($B$20,"!",LEFT(J$20,2),$V12,RIGHT(J$20,3),$V12),TRUE)),2) -> 1.43 | K12: =ROUND(AVERAGE(INDIRECT(_xlfn.CONCAT($B$20,"!",LEFT(K$20,2),$V12,RIGHT(K$20,3),$V12),TRUE)),2) -> 9.75 | L12: =ROUND(AVERAGE(INDIRECT(_xlfn.CONCAT($B$20,"!",LEFT(L$20,2),$V12,RIGHT(L$20,3),$V12),TRUE)),2) -> 4.98 | M12: =ROUND(AVERAGE(INDIRECT(_xlfn.CONCAT($B$20,"!",LEFT(M$20,2),$V12,RIGHT(M$20,3),$V12),TRUE)),2) -> 2.68 | N12: =ROUND(AVERAGE(INDIRECT(_xlfn.CONCAT($B$20,"!",LEFT(N$20,2),$V12,RIGHT(N$20,3),$V12),TRUE)),2) -> 6.09 | V12: 10 | X12: =_xlfn.CONCAT("raw!BC",V12,":BD",V12) -> raw!BC10:BD10 | Z12: =_xlfn.CONCAT("raw!AV",$V12,":BD",$V12) -> raw!AV10:BD10
B13: Depok City | C13: =GHSL!C11 -> 199.732 | D13: =GHSL!$X11/1000000 -> 60.768568 | E13: =D13/C13 -> 0.30425054 | F13: =GHSL!$N11/1000000 -> 3.225676 | G13: =GHSL!$N11/C13 -> 16150.021 | H13: =ROUND(AVERAGE(INDIRECT(_xlfn.CONCAT($B$20,"!",LEFT(H$20,2),$V13,RIGHT(H$20,3),$V13),TRUE)),2) -> 1.9 | I13: =ROUND(AVERAGE(INDIRECT(_xlfn.CONCAT($B$20,"!",LEFT(I$20,2),$V13,RIGHT(I$20,3),$V13),TRUE)),2) -> 0.43 | J13: =ROUND(AVERAGE(INDIRECT(_xlfn.CONCAT($B$20,"!",LEFT(J$20,2),$V13,RIGHT(J$20,3),$V13),TRUE)),2) -> 1.58 | K13: =ROUND(AVERAGE(INDIRECT(_xlfn.CONCAT($B$20,"!",LEFT(K$20,2),$V13,RIGHT(K$20,3),$V13),TRUE)),2) -> 5.55 | L13: =ROUND(AVERAGE(INDIRECT(_xlfn.CONCAT($B$20,"!",LEFT(L$20,2),$V13,RIGHT(L$20,3),$V13),TRUE)),2) -> 4.51 | M13: =ROUND(AVERAGE(INDIRECT(_xlfn.CONCAT($B$20,"!",LEFT(M$20,2),$V13,RIGHT(M$20,3),$V13),TRUE)),2) -> 3.29 | N13: =ROUND(AVERAGE(INDIRECT(_xlfn.CONCAT($B$20,"!",LEFT(N$20,2),$V13,RIGHT(N$20,3),$V13),TRUE)),2) -> 4.57 | V13: 11 | X13: =_xlfn.CONCAT("raw!BC",V13,":BD",V13) -> raw!BC11:BD11 | Z13: =_xlfn.CONCAT("raw!AV",$V13,":BD",$V13) -> raw!AV11:BD11
B14: Tangerang City | C14: =GHSL!C13 -> 181.467 | D14: =GHSL!$X13/1000000 -> 54.506128 | E14: =D14/C14 -> 0.30036386 | F14: =GHSL!$N13/1000000 -> 2.6003941 | G14: =GHSL!$N13/C14 -> 14329.846 | H14: =ROUND(AVERAGE(INDIRECT(_xlfn.CONCAT($B$20,"!",LEFT(H$20,2),$V14,RIGHT(H$20,3),$V14),TRUE)),2) -> 1.21 | I14: =ROUND(AVERAGE(INDIRECT(_xlfn.CONCAT($B$20,"!",LEFT(I$20,2),$V14,RIGHT(I$20,3),$V14),TRUE)),2) -> 0.22 | J14: =ROUND(AVERAGE(INDIRECT(_xlfn.CONCAT($B$20,"!",LEFT(J$20,2),$V14,RIGHT(J$20,3),$V14),TRUE)),2) -> 0.66 | K14: =ROUND(AVERAGE(INDIRECT(_xlfn.CONCAT($B$20,"!",LEFT(K$20,2),$V14,RIGHT(K$20,3),$V14),TRUE)),2) -> 4.04 | L14: =ROUND(AVERAGE(INDIRECT(_xlfn.CONCAT($B$20,"!",LEFT(L$20,2),$V14,RIGHT(L$20,3),$V14),TRUE)),2) -> 3.05 | M14: =ROUND(AVERAGE(INDIRECT(_xlfn.CONCAT($B$20,"!",LEFT(M$20,2),$V14,RIGHT(M$20,3),$V14),TRUE)),2) -> 2.13 | N14: =ROUND(AVERAGE(INDIRECT(_xlfn.CONCAT($B$20,"!",LEFT(N$20,2),$V14,RIGHT(N$20,3),$V14),TRUE)),2) -> 3.15 | V14: 13 | X14: =_xlfn.CONCAT("raw!BC",V14,":BD",V14) -> raw!BC13:BD13 | Z14: =_xlfn.CONCAT("raw!AV",$V14,":BD",$V14) -> raw!AV13:BD13
B15: South Tangerang City | C15: =GHSL!C14 -> 164.396 | D15: =GHSL!$X14/1000000 -> 49.95371 | E15: =D15/C15 -> 0.30386208 | F15: =GHSL!$N14/1000000 -> 1.8975224 | G15: =GHSL!$N14/C15 -> 11542.388 | H15: =ROUND(AVERAGE(INDIRECT(_xlfn.CONCAT($B$20,"!",LEFT(H$20,2),$V15,RIGHT(H$20,3),$V15),TRUE)),2) -> 1.53 | I15: =ROUND(AVERAGE(INDIRECT(_xlfn.CONCAT($B$20,"!",LEFT(I$20,2),$V15,RIGHT(I$20,3),$V15),TRUE)),2) -> 0.32 | J15: =ROUND(AVERAGE(INDIRECT(_xlfn.CONCAT($B$20,"!",LEFT(J$20,2),$V15,RIGHT(J$20,3),$V15),TRUE)),2) -> 1.14 | K15: =ROUND(AVERAGE(INDIRECT(_xlfn.CONCAT($B$20,"!",LEFT(K$20,2),$V15,RIGHT(K$20,3),$V15),TRUE)),2) -> 3.43 | L15: =ROUND(AVERAGE(INDIRECT(_xlfn.CONCAT($B$20,"!",LEFT(L$20,2),$V15,RIGHT(L$20,3),$V15),TRUE)),2) -> 3.44 | M15: =ROUND(AVERAGE(INDIRECT(_xlfn.CONCAT($B$20,"!",LEFT(M$20,2),$V15,RIGHT(M$20,3),$V15),TRUE)),2) -> 1.71 | N15: =ROUND(AVERAGE(INDIRECT(_xlfn.CONCAT($B$20,"!",LEFT(N$20,2),$V15,RIGHT(N$20,3),$V15),TRUE)),2) -> 3.05 | V15: 14 | X15: =_xlfn.CONCAT("raw!BC",V15,":BD",V15) -> raw!BC14:BD14 | Z15: =_xlfn.CONCAT("raw!AV",$V15,":BD",$V15) -> raw!AV14:BD14
A16: Outer suburbs | H16: =ROUND(AVERAGE(INDIRECT(_xlfn.CONCAT($B$20,"!",LEFT(H$20,2),$V16,RIGHT(H$20,3),$V16),TRUE)),2) -> 1.65 | I16: =ROUND(AVERAGE(INDIRECT(_xlfn.CONCAT($B$20,"!",LEFT(I$20,2),$V16,RIGHT(I$20,3),$V16),TRUE)),2) -> 0.44 | J16: =ROUND(AVERAGE(INDIRECT(_xlfn.CONCAT($B$20,"!",LEFT(J$20,2),$V16,RIGHT(J$20,3),$V16),TRUE)),2) -> 1.23 | K16: =ROUND(AVERAGE(INDIRECT(_xlfn.CONCAT($B$20,"!",LEFT(K$20,2),$V16,RIGHT(K$20,3),$V16),TRUE)),2) -> 3.73 | L16: =ROUND(AVERAGE(INDIRECT(_xlfn.CONCAT($B$20,"!",LEFT(L$20,2),$V16,RIGHT(L$20,3),$V16),TRUE)),2) -> 2.51 | M16: =ROUND(AVERAGE(INDIRECT(_xlfn.CONCAT($B$20,"!",LEFT(M$20,2),$V16,RIGHT(M$20,3),$V16),TRUE)),2) -> 1.57 | N16: =ROUND(AVERAGE(INDIRECT(_xlfn.CONCAT($B$20,"!",LEFT(N$20,2),$V16,RIGHT(N$20,3),$V16),TRUE)),2) -> 2.6
B17: Bogor Regency | C17: =GHSL!C7 -> 2993.32 | D17: =GHSL!$X7/1000000 -> 178.99097 | E17: =D17/C17 -> 0.059796803 | F17: =GHSL!$N7/1000000 -> 6.1805933 | G17: =GHSL!$N7/C17 -> 2064.7954 | H17: =ROUND(AVERAGE(INDIRECT(_xlfn.CONCAT($B$20,"!",LEFT(H$20,2),$V17,RIGHT(H$20,3),$V17),TRUE)),2) -> 3.73 | I17: =ROUND(AVERAGE(INDIRECT(_xlfn.CONCAT($B$20,"!",LEFT(I$20,2),$V17,RIGHT(I$20,3),$V17),TRUE)),2) -> 1.14 | J17: =ROUND(AVERAGE(INDIRECT(_xlfn.CONCAT($B$20,"!",LEFT(J$20,2),$V17,RIGHT(J$20,3),$V17),TRUE)),2) -> 3.15 | K17: =ROUND(AVERAGE(INDIRECT(_xlfn.CONCAT($B$20,"!",LEFT(K$20,2),$V17,RIGHT(K$20,3),$V17),TRUE)),2) -> 2.7 | L17: =ROUND(AVERAGE(INDIRECT(_xlfn.CONCAT($B$20,"!",LEFT(L$20,2),$V17,RIGHT(L$20,3),$V17),TRUE)),2) -> 2.85 | M17: =ROUND(AVERAGE(INDIRECT(_xlfn.CONCAT($B$20,"!",LEFT(M$20,2),$V17,RIGHT(M$20,3),$V17),TRUE)),2) -> 1 | N17: =ROUND(AVERAGE(INDIRECT(_xlfn.CONCAT($B$20,"!",LEFT(N$20,2),$V17,RIGHT(N$20,3),$V17),TRUE)),2) -> 2.39 | V17: 7 | X17: =_xlfn.CONCAT("raw!BC",V17,":BD",V17) -> raw!BC7:BD7 | Z17: =_xlfn.CONCAT("raw!AV",$V17,":BD",$V17) -> raw!AV7:BD7
B18: Bekasi Regency | C18: =GHSL!C10 -> 214.092 | D18: =GHSL!$X8/1000000 -> 131.83738 | E18: =D18/C18 -> 0.61579779 | F18: =GHSL!$N8/1000000 -> 3.7225789 | G18: =GHSL!$N8/C18 -> 17387.753 | H18: =ROUND(AVERAGE(INDIRECT(_xlfn.CONCAT($B$20,"!",LEFT(H$20,2),$V18,RIGHT(H$20,3),$V18),TRUE)),2) -> 2.15 | I18: =ROUND(AVERAGE(INDIRECT(_xlfn.CONCAT($B$20,"!",LEFT(I$20,2),$V18,RIGHT(I$20,3),$V18),TRUE)),2) -> 1.33 | J18: =ROUND(AVERAGE(INDIRECT(_xlfn.CONCAT($B$20,"!",LEFT(J$20,2),$V18,RIGHT(J$20,3),$V18),TRUE)),2) -> 2.19 | K18: =ROUND(AVERAGE(INDIRECT(_xlfn.CONCAT($B$20,"!",LEFT(K$20,2),$V18,RIGHT(K$20,3),$V18),TRUE)),2) -> 2.93 | L18: =ROUND(AVERAGE(INDIRECT(_xlfn.CONCAT($B$20,"!",LEFT(L$20,2),$V18,RIGHT(L$20,3),$V18),TRUE)),2) -> 4.26 | M18: =ROUND(AVERAGE(INDIRECT(_xlfn.CONCAT($B$20,"!",LEFT(M$20,2),$V18,RIGHT(M$20,3),$V18),TRUE)),2) -> 1.06 | N18: =ROUND(AVERAGE(INDIRECT(_xlfn.CONCAT($B$20,"!",LEFT(N$20,2),$V18,RIGHT(N$20,3),$V18),TRUE)),2) -> 3.16 | V18: 8 | X18: =_xlfn.CONCAT("raw!BC",V18,":BD",V18) -> raw!BC8:BD8 | Z18: =_xlfn.CONCAT("raw!AV",$V18,":BD",$V18) -> raw!AV8:BD8
B19: Tangerang Regency | C19: =GHSL!C12 -> 1026.623 | D19: =GHSL!$X12/1000000 -> 113.99801 | E19: =D19/C19 -> 0.11104174 | F19: =GHSL!$N12/1000000 -> 4.5350723 | G19: =GHSL!$N12/C19 -> 4417.4661 | H19: =ROUND(AVERAGE(INDIRECT(_xlfn.CONCAT($B$20,"!",LEFT(H$20,2),$V19,RIGHT(H$20,3),$V19),TRUE)),2) -> 2.85 | I19: =ROUND(AVERAGE(INDIRECT(_xlfn.CONCAT($B$20,"!",LEFT(I$20,2),$V19,RIGHT(I$20,3),$V19),TRUE)),2) -> 1 | J19: =ROUND(AVERAGE(INDIRECT(_xlfn.CONCAT($B$20,"!",LEFT(J$20,2),$V19,RIGHT(J$20,3),$V19),TRUE)),2) -> 2.11 | K19: =ROUND(AVERAGE(INDIRECT(_xlfn.CONCAT($B$20,"!",LEFT(K$20,2),$V19,RIGHT(K$20,3),$V19),TRUE)),2) -> 3.64 | L19: =ROUND(AVERAGE(INDIRECT(_xlfn.CONCAT($B$20,"!",LEFT(L$20,2),$V19,RIGHT(L$20,3),$V19),TRUE)),2) -> 3.88 | M19: =ROUND(AVERAGE(INDIRECT(_xlfn.CONCAT($B$20,"!",LEFT(M$20,2),$V19,RIGHT(M$20,3),$V19),TRUE)),2) -> 1.73 | N19: =ROUND(AVERAGE(INDIRECT(_xlfn.CONCAT($B$20,"!",LEFT(N$20,2),$V19,RIGHT(N$20,3),$V19),TRUE)),2) -> 3.33 | V19: 12 | X19: =_xlfn.CONCAT("raw!BC",V19,":BD",V19) -> raw!BC12:BD12 | Z19: =_xlfn.CONCAT("raw!AV",$V19,":BD",$V19) -> raw!AV12:BD12
A20: col_refs | B20: GHSL | C20: B | D20: W | F20: M | H20: BF:BG | I20: BM:BN | J20: BF:BN | K20: AW:AX | L20: AZ:BC | M20: BD:BE | N20: AW:BE
A26: GPRD Indonesia per Province | B26: 2023 (in billion IDR) | D26: population
A27: Jabodetabek | B27: =4550.01*1000 -> 4550010 | C27: =B27/B34 -> 0.22159253 | D27: 32281430 | E27: =D27/D34 -> 0.11327865
A28: Sumatra | B28: 4520134
A29: Java | B29: 11713356
A30: Bali & Nusa Tenggara | B30: 569274
A31: Kalimantan | B31: 1743461
A32: Sulawesi | B32: 1457789
A33: Maluku & Papua | B33: 529214
A34: TOTAL | B34: =SUM(B28:B33) -> 20533228 | D34: 284973643

Sheet GHSL
A1: Region | B1: GID_2 | C1: area_km2 | D1: Population_1980 | E1: Population_1985 | F1: Population_1990 | G1: Population_1995 | H1: Population_2000 | I1: Population_2005 | J1: Population_2010 | K1: Population_2015 | L1: Population_2020 | M1: Population_2025 | N1: Population_2030 | O1: BuiltUp_1980 | P1: BuiltUp_1985 | Q1: BuiltUp_1990 | R1: BuiltUp_1995 | S1: BuiltUp_2000 | T1: BuiltUp_2005 | U1: BuiltUp_2010 | V1: BuiltUp_2015 | W1: BuiltUp_2020 | X1: BuiltUp_2025 | Y1: BuiltUp_2030 | Z1: geometry | AA1: Pop_density_1980 | AB1: BU_density_1980 | AC1: Pop_density_1985 | AD1: BU_density_1985 | AE1: Pop_density_1990 | AF1: BU_density_1990 | AG1: Pop_density_1995 | AH1: BU_density_1995 | AI1: Pop_density_2000 | AJ1: BU_density_2000 | AK1: Pop_density_2005 | AL1: BU_density_2005 | AM1: Pop_density_2010 | AN1: BU_density_2010 | AO1: Pop_density_2015 | AP1: BU_density_2015 | AQ1: Pop_density_2020 | AR1: BU_density_2020 | AS1: Pop_density_2025 | AT1: BU_density_2025 | AU1: Pop_density_2030 | AV1: BU_density_2030 | AW1: Population_1980_to_1985_pct_change | AX1: Population_1985_to_1990_pct_change | AY1: Population_1990_to_1995_pct_change | AZ1: Population_1995_to_2000_pct_change | BA1: Population_2000_to_2005_pct_change | BB1: Population_2005_to_2010_pct_change | BC1: Population_2010_to_2015_pct_change | BD1: Population_2015_to_2020_pct_change | BE1: Population_2020_to_2025_pct_change | BF1: Population_2025_to_2030_pct_change | BG1: BuiltUp_1980_to_1985_pct_change | BH1: BuiltUp_1985_to_1990_pct_change | BI1: BuiltUp_1990_to_1995_pct_change | BJ1: BuiltUp_1995_to_2000_pct_change | BK1: BuiltUp_2000_to_2005_pct_change | BL1: BuiltUp_2005_to_2010_pct_change | BM1: BuiltUp_2010_to_2015_pct_change | BN1: BuiltUp_2015_to_2020_pct_change | BO1: BuiltUp_2020_to_2025_pct_change | BP1: BuiltUp_2025_to_2030_pct_change | BQ1: inc_20QTL | BR1: inc_40QTL | BS1: inc_60QTL | BT1: inc_80QTL | BU1: inc_100QTL | BV1: inc_total
A2: South Jakarta City | B2: IDN.7.3_1 | C2: 144.813 | D2: 1337682.9 | E2: 1550211.4 | F2: 1789282.7 | G2: 1804221.6 | H2: 1803292.6 | I2: 1916029.3 | J2: 2034290.2 | K2: 2129527.9 | L2: 2231248.6 | M2: 2363253 | N2: 2541613 | O2: 52427983 | P2: 53174407 | Q2: 53998958 | R2: 54819268 | S2: 55700757 | T2: 55837289 | U2: 55979757 | V2: 56107711 | W2: 56185188 | X2: 56194907 | Y2: 56204808 | Z2: POLYGON ((701679.8753645415 9314041.040531633, 701730.6315176925 9314030.325867828, 701765.6227672955 9314025.040518364, 701909.2203281845 9313991.654087376, 701973.6474841463 9313974.952928873, 702025.7332036326 9313964.642616436, 702075.7890368915 9313953.067351691, 702100.2191671961 9313947.25411124, 702142.3347737924 9313937.685876392, 702174.8389622085 9313930.163655968, 702203.130014752 9313923.784058204, 702203.1071536036 9313923.57399773, 702230.7123886428 9313917.318409113, 702280.788190475 9313905.123518443, 702348.2957964251 9313889.439840283, 702382.7291309421 9313882.86198979, 702407.514110339 9313877.24645854, 702430.329388199 9313871.770434758, 702473.148366745 9313863.969098797, 702501.8688441539 9313856.946376264, 702528.0249863907 9313850.950012874, 702561.7848609234 9313844.872069936, 702614.1084475298 9313836.152986627, 702695.13534799 9313825.056278326, 702750.4787285416 9313818.992081769, 702924.1257516125 9313791.714654721, 702924.0572747451 9313791.117651487, 702924.6118388159 9313791.447532307, 702993.0722579167 9313782.45102947, 702998.9903997014 9313781.446198998, 703036.1279394391 9313775.887142811, 703080.8668478818 9313769.560711812, 703090.1477282525 9313767.958042953, 703124.7491278312 9313761.97636984, 703165.26376938 9313756.7705052, 703206.6197961723 9313751.616994368, 703246.2861158752 9313744.356845567, 703274.9761450267 9313738.14118697, 703306.1900413593 9313728.808893204, 703338.4080810368 9313718.588294923, 703361.4453902221 9313710.124886898, 703407.3427489841 9313693.154412618, 703430.1681735448 9313684.238245426, 703436.7696061557 9313679.194082305, 703436.9020805991 9313679.094082288, 703458.0645492751 9313672.594759688, 703460.5302133566 9313671.845179906, 703500.171233177 9313657.307417313, 703521.8650109188 9313650.817282848, 703643.8929872182 9313605.699853092, 703674.6906304756 9313594.455382373, 703760.7366053391 9313562.557765003, 703805.7928907012 9313545.667253619, 703805.8815141593 9313545.689065566, 703843.7868132956 9313531.765357925, 703867.4320154265 9313523.078391671, 703904.3865747682 9313509.489744939, 703927.0917280504 9313501.027220974, 703943.1975596643 9313495.020864833, 703955.9650301158 9313490.253788076, 703955.6289008122 9313489.082591092, 703956.981506167 9313489.730427703, 704025.1018130884 9313465.747360317, 704121.4943345953 9313433.215832653, 704121.4271927682 9313433.005925126, 704143.1840921394 9313425.597309116, 704187.3502176378 9313410.57869356, 704222.1192870783 9313398.755970582, 704222.1410768029 9313398.656353936, 704222.1846177154 9313398.446060691, 704222.5281208658 9313398.555464359, 704261.507770601 9313384.871005654, 704282.9766743171 9313383.75651784, 704283.7177501086 9313383.610153252, 704313.2510231615 9313378.02138586, 704340.265270843 9313376.920721002, 704365.6087474579 9313379.154956652, 704366.6834157285 9313379.449830985, 704378.7569448008 9313378.832597367, 704400.3859559501 9313388.711235367, 704406.1803207332 9313390.305796571, 704434.9386233398 9313403.698784856, 704437.4912064495 9313405.658575935, 704437.5355569229 9313405.680541392, 704441.2979062195 9313408.587279703, 704465.4253971984 9313427.117236115, 704485.7384427116 9313440.495433215, 704494.2135701103 9313449.059553204, 704494.1584985723 9313449.137166034, 704494.0262574117 9313449.303528892, 704494.8475142329 9313449.931088533, 704494.5502514103 9313450.385589674, 704498.9765142046 9313453.234708805, 704500.9860586153 9313454.997311598, 704507.7735451625 9313458.88889973, 704533.4103037778 9313475.367455952, 704568.4600790079 9313493.217782488, 704578.9716768344 9313498.567359185, 704589.209041208 9313495.114052823, 704589.7988683619 9313496.029982092, 704603.5369845445 9313490.297131713, 704650.1468998198 9313474.594949575, 704657.6756800723 9313472.058015445, 704682.7960378969 9313454.749704162, 704694.9532022376 9313446.378983147, 704719.2239778955 9313417.17294197, 704732.9135201112 9313400.711916925, 704752.1030458546 9313377.61772353, 704761.2692841669 9313371.723836133, 704798.2653824744 9313347.892726595, 704798.3316378612 9313347.848254573, 704800.8275152412 9313346.246874975, 704819.910841672 9313333.947687093, 704833.4834354939 9313325.206992034, 704854.3216175819 9313314.638091955, 704864.956979391 9313311.06166997, 704892.3396248638 9313304.517872846, 704948.2882915557 9313291.16065241, 704960.8626183353 9313288.152553773, 704980.7458019886 9313279.865323843, 705030.9037667019 9313246.996089563, 705079.3279043384 9313215.260997666, 705108.2076750163 9313190.584285084, 705158.8493480657 9313147.327737365, 705169.6157356113 9313127.448149312, 705173.7647703964 9313117.501616465, 705176.5767691019 9313114.516590666, 705176.3879491822 9313114.329229783, 705190.8156983354 9313096.958519325, 705243.2322782144 9313080.140426708, 705263.5342010435 9313074.506033178, 705314.4437426996 9313060.358640231, 705401.4761580583 9313038.607865233, 705410.9210098261 9313036.440132728, 705448.954830253 9313027.724052316, 705488.5145950459 9313005.96267036, 705526.0985614636 9312976.300176136, 705544.1489524199 9312950.433483094, 705559.3735670954 9312926.77767, 705560.0009659876 9312925.780053549, 705590.3120902447 9312876.975766612, 705584.6922342794 9312874.650744483, 705584.923037458 9312874.185407488, 705598.3809551862 9312858.056683961, 705604.2269522664 9312839.676291801, 705603.3331766067 9312824.703974273, 705598.2274351886 9312814.336413592, 705589.7580650974 9312807.453554112, 705568.634394588 9312802.838217463, 705547.1255532469 9312798.854655353, 705532.1057056754 9312805.156372016, 705501.5473933638 9312786.68257878, 705500.9151432809 9312786.2976926, 705471.5193365611 9312742.680082733, 705463.3810053263 9312729.193139851, 705447.5389969341 9312706.221503174, 705433.0905568023 9312679.794208292, 705418.6217891595 9312647.571466396, 705416.5948397693 9312640.854008587, 705407.5127363511 9312610.746973284, 705394.6941455876 9312569.338519359, 705387.0003165677 9312540.575952822, 705386.9519936246 9312526.806237638, 705389.4422104228 9312514.144688427, 705394.4259714524 9312492.924892135, 705409.5518551213 9312469.557006868, 705434.7777918559 9312441.519453712, 705459.1652395342 9312411.106893362, 705472.6263779182 9312395.929336302, 705490.3128022897 9312383.10380842, 705503.8066723283 9312377.249835972, 705522.3668622549 9312373.700697217, 705543.4824538107 9312376.059759652, 705554.4950507918 9312385.400087487, 705563.8499968719 9312401.780498924, 705569.8899149569 9312413.416687915, 705570.5761046626 9312413.403217092, 705588.7204667872 9312455.312779255, 705617.0237254866 9312496.688943531, 705637.6995977133 9312515.639775546, 705646.170568246 9312519.834992513, 705650.7030307378 9312521.400669273, 705661.3102408013 9312522.458351558, 705668.3674952202 9312521.216933096, 705691.318851102 9312510.507452846, 705706.0671673242 9312499.406508856, 705712.0349396006 9312493.656365361, 705733.8295460849 9312471.901820662, 705758.2223530468 9312446.189646585, 705769.3158351914 9312434.448978709, 705778.1732608802 9312422.638749532, 705789.4174235833 9312419.126313113, 705791.063048196 9312418.114050074, 705805.4023815517 9312413.473647224, 705810.7006337796 9312412.481717128, 705813.022430583 9312411.75463955, 705815.3130844891 9312411.61386058, 705823.9627887007 9312409.97971108, 705833.9812754171 9312410.442178408, 705847.8579407568 9312409.574910797, 705856.5152145727 9312413.238553625, 705866.209011373 9312415.792531248, 705887.3452546849 9312424.00223969, 705904.3242119414 9312433.465310724, 705904.4794006003 9312433.531125726, 705905.144895138 9312433.926950457, 705927.1144089013 9312446.170681635, 706000.7303144289 9312487.099701993, 706018.1424561499 9312496.981513092, 706083.0541362478 9312527.168483935, 706115.79089122 9312538.732759967, 706129.7182260263 9312539.668066243, 706157.0957999781 9312538.067449454, 706177.2404253967 9312534.96599372, 706188.366838731 9312526.299844576, 706189.266564871 9312524.062515536, 706189.7558728495 9312515.290057631, 706189.763747608 9312511.241998795, 706180.669472346 9312493.511367738, 706176.8109427257 9312488.459393028, 706153.4871637783 9312462.56116825, 706132.3028401707 9312443.866648493, 706104.3614192494 9312420.49534447, 706084.8787080823 9312404.10640247, 706066.2331037412 9312386.553189434, 706058.6115177115 9312378.406551646, 706053.3506977253 9312371.169595418, 706039.4996696014 9312357.315717172, 706022.34112898 9312325.146756858, 706000.9008356038 9312296.59849352, 705967.8296662465 9312259.165610448, 705961.4497325192 9312251.57866655, 705950.2178929411 9312239.717453165, 705945.1304107187 9312231.407046832, 705936.4440272979 9312219.470510434, 705921.1649472116 9312196.098834902, 705893.9867764543 9312150.527023993, 705876.1441916659 9312118.946658297, 705858.2956665477 9312085.674106436, 705850.6939574536 9312073.722690566, 705843.5038227644 9312065.497105425, 705816.3279463837 9312017.403564952, 705810.7323350388 9312009.371450527, 705807.3142428068 9311997.361070104, 705806.7976740813 9311995.250394741, 705804.3084609683 9311989.286660867, 705804.3048938022 9311985.12804787, 705803.0247544604 9311979.912150806, 705805.5075872005 9311965.193380829, 705814.7437404122 9311947.807459338, 705825.679398726 9311938.434179887, 705847.5964364853 9311926.38991794, 705851.0568274383 9311925.260658113, 705856.5675961421 9311921.768361846, 705896.575859975 9311911.341530278, 705904.9573597112 9311909.000438415, 705905.7762062966 9311908.942253996, 705906.66083849 9311908.706875013, 705907.9450137502 9311908.779774088, 705923.5251967008 9311907.663129253, 705934.21544382 9311910.324164277, 705943.6807969558 9311910.888077118, 705957.3119223742 9311922.044031316, 705962.4359955268 9311925.034352725, 705970.803612777 9311931.32024372, 705972.5318389856 9311931.767623672, 705972.3683882422 9311932.498171577, 705978.5164588018 9311937.11073221, 705987.8798091679 9311955.846882557, 705992.1721976838 9311977.244280428, 705992.2335196006 9311994.652795702, 705981.3386083532 9312018.736012584, 705965.4091430944 9312049.539426375, 705957.0300799629 9312068.293824058, 705952.8397437569 9312079.014836796, 705954.5803365569 9312092.402588524, 705969.0206131681 9312116.451877067, 705989.3527646167 9312135.215768715, 706006.2619243164 9312140.586768148, 706067.9295543545 9312148.587264545, 706093.2696483207 9312149.924750973, 706115.2152045295 9312145.954236388, 706124.4777909975 9312139.219119802, 706136.2233424325 9312117.820495252, 706149.5678573352 9312069.617380612, 706160.4439325437 9312040.203167515, 706175.5226517194 9312006.715040676, 706187.2445143533 9311978.613995818, 706196.4741874406 9311962.5552271, 706211.6252759448 9311946.464513661, 706236.0139378227 9311919.701302059, 706254.5032175444 9311892.947823398, 706277.1842458392 9311862.175752075, 706299.880921216 9311832.708713194, 706329.3497623341 9311805.927508395, 706347.842020161 9311783.17775953, 706367.1958395027 9311763.068348465, 706381.4757990749 9311741.660675185, 706389.8405297622 9311718.902414365, 706396.4881643885 9311689.447726326, 706394.7207146478 9311665.353771098, 706392.102831061 9311654.31386596, 706388.7206006564 9311639.958597206, 706375.985960432 9311622.539493918, 706352.3063533473 9311611.817278566, 706322.735371621 9311606.491113866, 706299.9347123734 9311606.460996745, 706275.010813487 9311613.229328837, 706270.3997523224 9311614.473284863, 706243.3916768986 9311617.156682458, 706220.5959008241 9311618.509040907, 706207.9244864502 9311615.855059888, 706196.921142051 9311609.147159074, 706185.9036370408 9311598.424455147, 706185.0200498886 9311586.405137468, 706184.9774412127 9311574.327551926, 706187.4545544117 9311558.027141284, 706192.4208923368 9311550.820490649, 706192.4869495863 9311550.720715804, 706203.4136404411 9311535.706654016, 706222.7296059676 9311504.891139032, 706246.2399557953 9311467.679070892, 706270.613873323 9311433.682454374, 706295.8138580099 9311395.413663074, 706310.0793745025 9311369.946940675, 706319.2792279093 9311345.493518626, 706321.7124904646 9311316.794750093, 706323.1771008767 9311255.139985261, 706324.2499010938 9311220.440326829, 706324.697800743 9311206.237438831, 706327.9647797438 9311175.434281623, 706328.7271445023 9311153.12314999, 706328.6453684323 9311129.974424297, 706322.6869586975 9311116.38035799, 706311.6464873736 9311096.013277698, 706302.3011213465 9311082.386935404, 706283.6664081821 9311064.72325027, 706259.9418535652 9311044.345669368, 706232.8526512494 9311023.979966389, 706209.994700331 9311007.658408586, 706193.8946446385 9310989.996819278, 706176.0852894918 9310970.969798999, 706160.8072447813 9310947.874746354, 706151.4491819949 9310927.501720838, 706148.8570610672 9310911.208140599, 706155.5461449199 9310893.521385418, 706164.7904972846 9310878.557474244, 706179.9294489854 9310862.267639825, 706206.0479069573 9310845.972200133, 706226.6781668336 9310833.257517, 706234.6961440685 9310828.318462713, 706272.6111395665 9310805.190342367, 706305.4729101161 9310783.451512761, 706333.2641733456 9310764.473511912, 706356.8478444518 9310748.142697137, 706378.7059289783 9310719.585375167, 706423.2585354868 9310661.151562661, 706434.2104831719 9310647.09953427, 706451.8394170734 9310624.49645646, 706469.4502473753 9310590.52352913, 706488.7160109647 9310545.683598906, 706491.3703193642 9310532.601027435, 706494.5252950629 9310517.12767629, 706495.3136566816 9310502.204650167, 706491.8903562728 9310488.767537475, 706481.7047732758 9310475.409656182, 706463.945646314 9310467.453839654, 706436.0621590526 9310463.43809647, 706399.7872869149 9310471.419177229, 706378.6758308427 9310470.078144083, 706371.0579976703 9310466.090230364, 706366.7970529693 9310456.770481188, 706366.7170561693 9310434.152629405, 706375.901008039 9310402.156129368, 706389.3381535495 9310383.54955781, 706410.3520600803 9310354.198825246, 706429.6667222574 9310335.715224126, 706442.3299220968 9310323.603716463, 706464.2039973899 9310299.636231765, 706478.4884572881 9310279.655157173, 706491.9064697524 9310255.662283188, 706502.7681488337 9310222.398927273, 706522.8353999279 9310166.418453556, 706536.1607848266 9310113.160531607, 706543.6401040097 9310081.16999546, 706546.8665924941 9310035.911189687, 706544.2282086266 9310006.599880094, 706537.4437853452 9309997.289082322, 706526.4407891235 9309990.625559872, 706510.3876263236 9309989.310949966, 706498.5905651413 9309995.94462278, 706468.2812803399 9310022.585422412, 706450.6352458097 9310046.537974117, 706430.525609529 9310090.540351355, 706412.1546108536 9310150.463269925, 706392.0934901258 9310205.072187228, 706373.6563315581 9310246.325661756, 706364.3892373675 9310251.678410882, 706339.0641133684 9310254.356091399, 706313.7294843907 9310254.34616274, 706279.9263600769 9310247.652625114, 706237.6284410543 9310223.702004137, 706209.6886111477 9310203.704396073, 706191.0413093698 9310182.41306658, 706172.3641076824 9310155.790823106, 706157.0407101425 9310119.832972996, 706152.884469796 9310108.809583789, 706137.4328963088 9310067.897218343, 706122.9176450532 9310022.590645434, 706110.9322738411 9309975.95896831, 706102.3885742797 9309947.984744176, 706097.2380613447 9309924.953495482, 706088.0762983204 9309894.338070352, 706085.2762058406 9309884.968919992, 706077.5580719248 9309849.448725231, 706070.6885148385 9309819.157005783, 706065.5172889938 9309790.263928713, 706063.7304035974 9309760.68421603, 706061.0415247179 9309717.02806034, 706062.6009558908 9309682.271404412, 706061.6787067316 9309659.33581397, 706063.2357401741 9309620.774456907, 706063.1089103762 9309584.90668133, 706063.8558765394 9309558.271081343, 706063.8502053707 9309556.667372568, 706063.8436737327 9309554.82034246, 706063.8426568294 9309554.532780886, 706063.7701036017 9309534.016368562, 706064.492419478 9309500.412929554, 706064.4107462334 9309477.31952263, 706062.6465889467 9309454.176765164, 706059.225808959 9309441.425394025, 706051.5240221275 9309413.658354055, 706035.328370752 9309371.996566536, 706023.3771600527 9309335.009293139, 706012.291389737 9309304.887342807, 706007.1353763988 9309277.166604681, 706006.1918269868 9309248.214346813, 706006.1099511988 9309225.065644493, 706017.7993848431 9309188.05005715, 706019.309188195 9309183.089747757, 706025.3351730125 9309159.510208737, 706017.5078680604 9309158.830046026, 706037.8968561473 9309131.295441404, 706052.1040351505 9309102.068366786, 706067.2338562331 9309080.237293458, 706085.7283701982 9309058.438545085, 706099.1521394629 9309033.029988479, 706121.8231118333 9308996.716508716, 706149.5693476296 9308962.17679409, 706173.9419523616 9308931.343112841, 706191.6047949628 9308912.245939802, 706213.4827049648 9308889.539258735, 706224.4169126078 9308876.847644458, 706231.988163494 9308867.740389049, 706233.638303327 9308858.665169777, 706230.2240218518 9308847.760837425, 706214.9862165342 9308835.947214318, 706174.4960553306 9308819.046860162, 706158.30935785 9308814.304061195, 706053.0997160237 9308761.100976406, 706039.9116505411 9308756.148452736, 706036.4351399504 9308752.665736165, 706029.5276161144 9308749.173044538, 706029.237812134 9308745.468903376, 706027.1941432152 9308743.430000689, 706022.9023613991 9308722.24278986, 706022.8273069869 9308701.040652428, 706026.9241820793 9308667.17087655, 706028.9311345522 9308661.96547723, 706029.5236764401 9308657.395516662, 706034.5020193469 9308647.423710745, 706056.2156508383 9308590.851317616, 706083.817783702 9308518.818001453, 706098.8145578583 9308459.493242122, 706098.754571239 9308442.560280427, 706080.7576486887 9308407.91711312, 706078.8561388645 9308405.391062422, 706060.5532458664 9308387.472006816, 706059.7767994178 9308386.988108246, 706033.9677094612 9308374.647858068, 705990.1291791799 9308359.086568864, 705985.8087978638 9308357.951607337, 705955.5083463185 9308352.440317117, 705952.7264212235 9308351.322026726, 705924.2247422049 9308347.452322545, 705912.5771500336 9308352.43746254, 705899.2476745478 9308373.167209234, 705890.3713336838 9308429.417590713, 705884.4465437776 9308475.305179335, 705874.0865213848 9308534.524928752, 705872.3959893316 9308541.576252624, 705867.8434459959 9308571.797743775, 705859.1448361466 9308596.979393233, 705857.803449947 9308602.613775836, 705842.9947463608 9308658.87404747, 705829.6755918252 9308682.5567814, 705804.5123805825 9308686.992426353, 705774.9070317454 9308684.033441434, 705773.963125636 9308686.270936448, 705774.3537737379 9308684.068578217, 705774.4274142155 9308679.854387047, 705728.0089820529 9308667.122323243, 705683.1726648579 9308641.698609388, 705580.8067034538 9308537.906659778, 705556.6175143745 9308501.615208771, 705533.0045220747 9308440.447391702, 705516.300930647 9308364.523018805, 705512.2650025507 9308306.062147025, 705514.0958170929 9308260.399285885, 705514.2783037566 9308255.66488716, 705521.3384997617 9308233.486412313, 705526.382871948 9308223.40382844, 705537.2946075144 9308213.765034897, 705583.756773341 9308226.463796668, 705653.9863021916 9308268.830375716, 705695.7256352662 9308298.00331982, 705723.9535777438 9308312.115822976, 705751.1651499829 9308311.101577327, 705809.6337804686 9308291.948619902, 705836.3763154235 9308270.983406384, 705861.537377739 9308222.218448317, 705863.0571589782 9308198.201390289, 705855.6093523703 9308182.754544761, 705855.4849094173 9308181.991831986, 705854.9739290907 9308181.462751519, 705848.9532466808 9308168.974985965, 705820.7199755843 9308137.719277825, 705776.698098213 9308107.80242205, 705736.0789763026 9308082.419242883, 705718.9102662187 9308072.194015672, 705712.8653344852 9308059.098023342, 705706.3750814339 9308042.132542085, 705709.8439902455 9308027.84157066, 705723.1666959989 9308014.599630814, 705763.2612599541 9308013.738834495, 705810.6452022423 9308011.713007355, 705826.7713284809 9308005.672356488, 705834.837057539 9307995.590086982, 705837.8642002507 9307978.447131868, 705837.7594335545 9307945.731454005, 705824.9041704439 9307890.92947863, 705824.7794140875 9307890.07828559, 705824.7112085191 9307889.569758264, 705823.1677089485 9307878.747295702, 705806.9638199103 9307831.555532563, 705791.5348970762 9307768.799340144, 705781.315986825 9307727.138606679, 705767.3014633192 9307669.995989632, 705758.2261859836 9307607.493814928, 705737.0546122547 9307510.725774044, 705718.9151706472 9307448.233586906, 705703.7874754474 9307404.88698271, 705691.6979661672 9307375.65347982, 705667.5028792552 9307359.52492189, 705644.0050620682 9307355.902956914, 705609.3940006641 9307358.082678245, 705570.5856698675 9307368.870992515, 705530.0721779128 9307373.184046237, 705458.3154761678 9307377.496987542, 705398.3940864818 9307386.14781508, 705339.3934494607 9307414.194852121, 705309.1211276626 9307450.910997225, 705297.3989364763 9307462.919521261, 705283.8793055173 9307476.781440096, 705274.6471883217 9307491.900123188, 705245.0896191086 9307489.737220623, 705184.2430479885 9307474.611714203, 705152.0714931772 9307453.047427852, 705149.4836255246 9307437.915214315, 705149.2222439199 9307435.98061022, 705147.7557856917 9307425.003054949, 705153.6276818227 9307414.220786547, 705183.9306418705 9307386.164740494, 705285.9332594 9307340.822657598, 705370.2364224027 9307304.125626603, 705443.6252988307 9307282.5641863, 705460.8559284273 9307272.825581035, 705461.8649330903 9307257.713814242, 705459.8489475428 9307241.584153052, 705450.7787389725 9307230.489707144, 705428.1930805914 9307215.638372976, 705393.5515446581 9307209.169043455, 705353.0076072314 9307204.833060035, 705227.1407094067 9307189.71636756, 705167.1357013946 9307174.632203208, 705134.161198989 9307163.832324373, 705124.0194525572 9307159.543630075, 705119.7688957048 9307153.077394336, 705114.6880670167 9307146.54773048, 705112.0719700567 9307129.690236224, 705117.1213687989 9307108.525383648, 705140.3151784929 9307082.540558364, 705184.4232966278 9307049.48072833, 705251.0113491557 9307017.071348779, 705264.4788336983 9307004.149703942, 705270.289521025 9306976.080583215, 705273.7028887414 9306942.965442223, 705275.190417072 9306928.593028536, 705288.0763492314 9306860.77076617, 705288.315444948 9306859.531181997, 705288.4349928019 9306858.911389908, 705288.4457469935 9306858.822870547, 705288.6094068938 9306858.15868178, 705288.7728320807 9306857.428132847, 705290.9417056605 9306847.952960024, 705293.8880898366 9306836.141341789, 705313.4209622156 9306757.688845098, 705325.9300967157 9306711.656409996, 705341.0212851933 9306682.22720236, 705373.7116629134 9306615.927448504, 705390.4307085563 9306568.033022502, 705386.9835581707 9306547.794050349, 705383.5689063843 9306536.73490639, 705377.6329337633 9306529.36772561, 705368.3411208154 9306527.553570155, 705357.3558511246 9306525.690106992, 705337.0983852957 9306527.553557564, 705320.2357913647 9306534.890829565, 705301.693004529 9306545.92813707, 705278.170745702 9306579.081266956, 705267.2943252006 9306604.856752709, 705252.1595970972 9306625.106154533, 705242.8808465347 9306626.98602417, 705222.6037933778 9306623.319411099, 705208.1649044125 9306599.36992758, 705208.065884348 9306596.406154405, 705206.2631003448 9306540.414930744, 705212.931711585 9306526.510839062, 705223.0279280801 9306505.438694943, 705266.8317470364 9306474.116173152, 705331.6906872514 9306431.802690495, 705334.1643433489 9306430.278690927, 705370.4405917082 9306407.83084012, 705398.2099435488 9306380.203741511, 705416.6809372092 9306348.91545561, 705419.9390621671 9306315.77869207, 705413.0792488884 9306288.174672078, 705394.4954951967 9306284.49109285, 705324.4312257422 9306288.167845894, 705285.5661734057 9306295.218036119, 705263.6783527074 9306299.199747276, 705234.137552903 9306304.734834747, 705200.4322617002 9306324.994656563, 705172.0531640566 9306346.076182725, 705158.3327245603 9306356.266883865, 705130.511245462 9306369.17295097, 705093.3782776416 9306374.690561898, 705066.3373472738 9306367.34268798, 705047.69688857 9306350.740937836, 705047.6613023559 9306350.066394264, 705045.8911016962 9306315.786175871, 705053.3464017642 9306277.104578024, 705053.2552047627 9306251.312620325, 705038.8099528078 9306225.527176907, 705015.9726042815 9306214.481407719, 704988.9513508744 9306212.674588602, 704937.4774358615 9306221.870548014, 704905.8675988793 9306227.534444846, 704875.8835921092 9306232.905014887, 704839.5333070463 9306221.851624051, 704820.5662221257 9306209.87412633, 704813.3010206126 9306205.276648618, 704809.7955843207 9306168.480880832, 704823.9691018767 9306117.377200853, 704825.5314679735 9306114.783608258, 704853.3470080486 9306068.907402199, 704883.6100417485 9306029.780268177, 704881.845032834 9306009.480078481, 704874.0483956945 9305954.715672724, 704850.2321627893 9305904.642089011, 704834.9873238424 9305890.561102144, 704801.9688880349 9305867.108618721, 704757.9941163711 9305846.791672375, 704734.9378113035 9305842.626030907, 704723.3542874102 9305840.532342559, 704687.8953788097 9305840.502743341, 704642.6412560337 9305855.892354595, 704637.2912398938 9305857.714046236, 704611.9754976875 9305862.448680177, 704580.7220763107 9305859.285208203, 704556.1866236206 9305843.655366553, 704534.0860273086 9305802.96573827, 704531.3494819002 9305798.982690526, 704513.7174080743 9305773.241642637, 704489.9624436 9305740.421600664, 704477.7641235968 9305730.311451616, 704419.3477885431 9305681.930444798, 704416.2843615308 9305679.397424515, 704363.3110666955 9305649.268501457, 704349.8044181451 9305641.596177876, 704309.845864421 9305617.714525886, 704304.4106920426 9305607.934430525, 704297.0932528966 9305594.765517456, 704291.8569932061 9305591.178384503, 704289.7813634577 9305586.30819333, 704289.3015117174 9305585.181753758, 704291.647886521 9305575.816623533, 704292.3097525584 9305562.65275386, 704292.3423680179 9305562.486737134, 704295.2335302061 9305547.55644762, 704310.466030839 9305533.10245857, 704314.2383241791 9305529.527797101, 704341.3944508097 9305513.217882333, 704386.0716510646 9305491.227592455, 704402.671814225 9305478.60472215, 704405.5375347645 9305478.428708054, 704425.7083254725 9305477.218334667, 704495.8549279554 9305497.221829403, 704501.4946196876 9305499.093201507, 704544.0415424032 9305513.18842891, 704583.749004028 9305519.219763508, 704600.6988544004 9305521.006942993, 704640.3444796917 9305525.191418214, 704667.7565202494 9305531.210832471, 704691.90011387 9305529.919973578, 704701.7741110073 9305518.028616527, 704704.6723795738 9305514.534431655, 704705.3289706493 9305509.300666321, 704701.3940471715 9305498.165952584, 704668.6663206604 9305466.085539265, 704625.1242456981 9305442.847189467, 704610.2200204385 9305428.02396136, 704610.184553936 9305427.382598953, 704602.1456879805 9305419.912226245, 704594.3622204072 9305412.684273759, 704556.2220496594 9305377.238547394, 704532.532601222 9305347.282901075, 704520.1655459909 9305330.11701615, 704484.8660651228 9305281.112584542, 704456.1171848748 9305241.209622249, 704413.7063957936 9305187.242172759, 704411.4496910723 9305184.374507884, 704408.9706751877 9305181.231124764, 704391.6507322005 9305159.216264868, 704384.40309322 9305147.00935571, 704384.1068602463 9305135.198192215, 704381.4045564993 9305125.231502565, 704391.0341970765 9305109.967720669, 704393.9945573107 9305105.256717715, 704405.7857274623 9305097.251800345, 704424.0969744626 9305095.992652826, 704432.8654060037 9305093.838146944, 704434.5903343565 9305093.411771184, 704444.4993689132 9305094.593393212, 704449.2790710842 9305094.2557705, 704453.8817834713 9305093.94089267, 704464.038714389 9305093.241414683, 704506.2830826198 9305103.223281575, 704515.5651676782 9305099.230966829, 704525.6489696451 9305087.228284394, 704528.1409778098 9305075.252420554, 704522.4746736453 9305065.838148704, 704513.7024245192 9305051.2476491, 704479.7708105537 9305007.226545991, 704470.9841982585 9305001.097092947, 704428.1384798182 9304971.231244428, 704397.6218610676 9304935.260892875, 704372.1274185239 9304889.263392555, 704370.0999562575 9304860.425755573, 704369.4588712994 9304851.248118736, 704371.9225681096 9304831.253779024, 704381.938870596 9304800.150522744, 704387.7823476193 9304781.405096896, 704387.7236730903 9304764.792999884, 704390.1771157797 9304741.900939817, 704415.3328348821 9304692.019398034, 704416.4653166821 9304689.925033493, 704442.1817391157 9304642.142908612, 704496.0261064367 9304590.158030411, 704566.7914025863 9304544.406453067, 704604.7690114031 9304540.257311037, 704639.4080714034 9304546.516482629, 704654.6798966504 9304565.187270634, 704658.3821533616 9304569.996393526, 704669.0997546643 9304583.905312112, 704677.5842420824 9304598.485739233, 704681.8337386118 9304604.69756346, 704684.8239299809 9304605.306352, 704702.1117165186 9304608.839730635, 704729.1001630932 9304598.469358353, 704777.8496424798 9304564.132032227, 704779.0971217849 9304563.264924968, 704791.3883581082 9304546.509533014, 704783.5376568174 9304498.392509267, 704782.9945933917 9304495.043207567, 704780.5534263882 9304483.83686183, 704769.074817382 9304442.534674464, 704753.4284099354 9304421.221865902, 704746.1668158285 9304411.337683221, 704729.2126953934 9304392.628636165, 704696.2265040213 9304378.079646152, 704660.7319000801 9304367.70919185, 704612.5511306436 9304353.169692988, 704610.9655134038 9304352.301552167, 704593.8897082731 9304342.97190915, 704589.7094963212 9304340.697249638, 704583.7409620984 9304324.050740184, 704585.3826607033 9304309.4897937, 704597.7756320491 9304268.324360635, 704600.4007780799 9304259.59968438, 704625.5558521784 9304209.67368846, 704657.7385162355 9304144.194354482, 704658.2549651088 9304143.152873078, 704685.9553363828 9304099.499968914, 704697.7303372911 9304087.004555687, 704701.928472236 9304078.716703175, 704739.8320214987 9304053.741386686, 704775.2823628134 9304051.658171453, 704798.1093873708 9304060.01619736, 704807.5305768056 9304073.476201523, 704810.4559362952 9304077.6576339, 704818.4756104999 9304089.109655954, 704831.2942605368 9304130.672524357, 704839.9813657429 9304199.314221364, 704846.0235649663 9304236.731425531, 704856.3645443266 9304247.412076268, 704862.1181287903 9304253.342053622, 704874.6976975187 9304258.650597895, 704891.1704200495 9304260.17383319, 704929.1729622178 9304263.102826955, 704939.4154487927 9304267.844514014, 704953.1053398743 9304274.17770371, 704977.0425337199 9304280.363966316, 704996.2250273438 9304293.922082169, 705032.9148262774 9304319.871864952, 705087.0424299231 9304344.841803217, 705098.8789494603 9304343.450485911, 705112.1203833128 9304341.899340812, 705129.6871479102 9304339.846203055, 705133.5355569854 9304335.928313471, 705145.2240588526 9304324.008231468, 705153.5206858958 9304282.481048865, 705145.7923481789 9304247.115930118, 705087.1386262994 9304134.831058858, 705044.2724618387 9304086.70549652, 705037.1170215785 9304078.679077573, 705013.5069440347 9304049.254303815, 704987.0845344091 9304016.31130963, 704938.7230485235 9303950.774399184, 704924.2951013473 9303929.778077904, 704922.6235663553 9303920.283330178, 704921.7087056284 9303915.077240288, 704917.4476461202 9303902.48377037, 704915.709798747 9303889.89241432, 704913.1160707125 9303873.123354098, 704915.605640535 9303860.51700875, 704919.781054491 9303845.836435694, 704929.9181967763 9303845.855789442, 704936.691022201 9303852.102880832, 704950.3686411913 9303870.602260387, 704953.7692018182 9303874.59397792, 704958.6478890106 9303880.350078631, 704975.4412661034 9303897.422705965, 704986.4258988163 9303908.609808441, 705010.430949069 9303933.963033224, 705045.9632218009 9303954.984018076, 705071.3246837689 9303963.377186375, 705100.001804935 9303954.947127542, 705119.3345283541 9303929.771941114, 705136.1255329162 9303902.504332654, 705136.111910752 9303898.666502489, 705135.7679557635 9303801.769584376, 705132.109410307 9303721.99451302, 705129.5528734401 9303715.721413435, 705125.3140688004 9303709.410045687, 705116.0450458433 9303695.186395278, 705109.3414792864 9303692.865437971, 705096.532646888 9303688.420480639, 705077.1255185143 9303692.603751564, 705018.1004732104 9303715.696707033, 705007.3429178474 9303718.59945961, 704909.286740409 9303745.093504407, 704875.3405185603 9303746.861841617, 704829.0904961298 9303749.282083895, 704780.9430110764 9303740.903247174, 704754.7682827153 9303734.06129511, 704732.7695538455 9303728.310550755, 704714.1401661255 9303711.49877638, 704705.3025986922 9303694.077179484, 704701.3797237781 9303686.337916806, 704694.5398604476 9303661.156080961, 704730.6598021137 9303610.759728745, 704820.7993872266 9303552.009427857, 704871.3728583255 9303526.778832087, 704876.4042270212 9303519.428103656, 704876.5912978253 9303519.128815936, 704896.5519012426 9303486.92825894, 704894.780382104 9303461.728446275, 704896.1795763087 9303381.97975114, 704884.3009317524 9303365.199396886, 704875.8198047493 9303354.678097092, 704858.9099782265 9303348 | AA2: 9237.3125 | AB2: 362039.2 | AC2: 10704.919 | AD2: 367193.6 | AE2: 12355.815 | AF2: 372887.5 | AG2: 12458.975 | AH2: 378552.12 | AI2: 12452.56 | AJ2: 384639.2 | AK2: 13231.059 | AL2: 385582.02 | AM2: 14047.704 | AN2: 386565.83 | AO2: 14705.364 | AP2: 387449.41 | AQ2: 15407.792 | AR2: 387984.42 | AS2: 16319.343 | AT2: 388051.54 | AU2: 17551 | AV2: 388119.91 | AW2: 3.1775608 | AX2: 3.0843708 | AY2: 0.16698153 | AZ2: -0.010297597 | BA2: 1.2503425 | BB2: 1.2344373 | BC2: 0.93632406 | BD2: 0.95533575 | BE2: 1.1832333 | BF2: 1.5094448 | BG2: 0.2847426 | BH2: 0.31013077 | BI2: 0.30382438 | BJ2: 0.32159824 | BK2: 0.049023391 | BL2: 0.051029698 | BM2: 0.045714382 | BN2: 0.027617238 | BO2: 0.0034596307 | BP2: 0.0035238069 | BQ2: 81598.531 | BR2: 188417.4 | BS2: 395705.11 | BT2: 638528.89 | BU2: 1015813.1 | BV2: 2320063
